Workbook

Sheet Read me
A1: Naira on the Plate
A2: Nigerian food prices, Jan 2019 to Jul 2026, national average across 68 markets.
A4: Sheet | B4: What it shows
A5: Pick a food | B5: Choose any food in the yellow cell. The stats and chart update to show its price since 2019.
A6: Peak to now | B6: Each food's price in Jan 2023, its peak, and how far it has fallen since. Green = fell the most.
A7: By zone | B7: Cost of 1 kg each of rice, beans and garri in the five geopolitical zones, with a chart.
A8: Prices | B8: The data: monthly national average price for 15 foods (in each food's own unit).
A9: Zones | B9: The data: monthly rice, beans and garri prices for each zone, plus the plate cost formula.
A11: Source | B11: World Bank, Monthly food price estimates by product and market, Nigeria. File: NGA_RTFP_mkt_2007_2026-08-03.csv. https://microdata.worldbank.org/catalog/4503
A12: About the prices | B12: These are the World Bank's monthly estimated (close) prices. Since 2019 only about a quarter were directly collected. The rest are model estimates.
A13: Formulas | B13: Only the Prices and Zones sheets contain typed-in data. Every other number is a formula, so you can trace it with Formulas > Trace Precedents.
A14: Full analysis | B14: SQL, charts and write-up: github.com/midexol/data-analyst-portfolio (01-nigeria-food-prices)

Sheet Pick a food
A1: Pick a food to see its price since 2019
A3: Food | B3: Beans (2.5 kg) | C3: Change this cell (dropdown)
A5: Jan 2023 | B5: =INDEX('Peak to now'!$B$5:$B$19,MATCH($B$3,'Peak to now'!$A$5:$A$19,0)) -> 1077.85
A6: Peak | B6: =INDEX('Peak to now'!$C$5:$C$19,MATCH($B$3,'Peak to now'!$A$5:$A$19,0)) -> 4596.67
A7: Peak month | B7: =INDEX('Peak to now'!$D$5:$D$19,MATCH($B$3,'Peak to now'!$A$5:$A$19,0)) -> 45536
A8: Jul 2026 | B8: =INDEX('Peak to now'!$E$5:$E$19,MATCH($B$3,'Peak to now'!$A$5:$A$19,0)) -> 2276.95
A9: Down from peak | B9: =INDEX('Peak to now'!$G$5:$G$19,MATCH($B$3,'Peak to now'!$A$5:$A$19,0)) -> -0.50465228
A10: Jan 2023 to now | B10: =INDEX('Peak to now'!$H$5:$H$19,MATCH($B$3,'Peak to now'!$A$5:$A$19,0)) -> 1.1124925
A13: Month | B13: Price (naira) | C13: Index (Jan 2023 = 100) | D13: Year label
A14: =Prices!A2 -> 43466 | B14: =INDEX(Prices!$B$2:$P$2,MATCH($B$3,Prices!$B$1:$P$1,0)) -> 536.73 | C14: =B14/$B$5*100 -> 49.796354 | D14: =IF(MONTH(A14)=1,YEAR(A14),"") -> 2019
A15: =Prices!A3 -> 43497 | B15: =INDEX(Prices!$B$3:$P$3,MATCH($B$3,Prices!$B$1:$P$1,0)) -> 539.41 | C15: =B15/$B$5*100 -> 50.044997 | D15: =IF(MONTH(A15)=1,YEAR(A15),"")
A16: =Prices!A4 -> 43525 | B16: =INDEX(Prices!$B$4:$P$4,MATCH($B$3,Prices!$B$1:$P$1,0)) -> 555.47 | C16: =B16/$B$5*100 -> 51.535 | D16: =IF(MONTH(A16)=1,YEAR(A16),"")
A17: =Prices!A5 -> 43556 | B17: =INDEX(Prices!$B$5:$P$5,MATCH($B$3,Prices!$B$1:$P$1,0)) -> 488.5 | C17: =B17/$B$5*100 -> 45.321705 | D17: =IF(MONTH(A17)=1,YEAR(A17),"")
A18: =Prices!A6 -> 43586 | B18: =INDEX(Prices!$B$6:$P$6,MATCH($B$3,Prices!$B$1:$P$1,0)) -> 457.3 | C18: =B18/$B$5*100 -> 42.427054 | D18: =IF(MONTH(A18)=1,YEAR(A18),"")
A19: =Prices!A7 -> 43617 | B19: =INDEX(Prices!$B$7:$P$7,MATCH($B$3,Prices!$B$1:$P$1,0)) -> 462.76 | C19: =B19/$B$5*100 -> 42.933618 | D19: =IF(MONTH(A19)=1,YEAR(A19),"")
A20: =Prices!A8 -> 43647 | B20: =INDEX(Prices!$B$8:$P$8,MATCH($B$3,Prices!$B$1:$P$1,0)) -> 426.73 | C20: =B20/$B$5*100 -> 39.590852 | D20: =IF(MONTH(A20)=1,YEAR(A20),"")
A21: =Prices!A9 -> 43678 | B21: =INDEX(Prices!$B$9:$P$9,MATCH($B$3,Prices!$B$1:$P$1,0)) -> 411.69 | C21: =B21/$B$5*100 -> 38.195482 | D21: =IF(MONTH(A21)=1,YEAR(A21),"")
A22: =Prices!A10 -> 43709 | B22: =INDEX(Prices!$B$10:$P$10,MATCH($B$3,Prices!$B$1:$P$1,0)) -> 460.77 | C22: =B22/$B$5*100 -> 42.748991 | D22: =IF(MONTH(A22)=1,YEAR(A22),"")
A23: =Prices!A11 -> 43739 | B23: =INDEX(Prices!$B$11:$P$11,MATCH($B$3,Prices!$B$1:$P$1,0)) -> 352.99 | C23: =B23/$B$5*100 -> 32.749455 | D23: =IF(MONTH(A23)=1,YEAR(A23),"")
A24: =Prices!A12 -> 43770 | B24: =INDEX(Prices!$B$12:$P$12,MATCH($B$3,Prices!$B$1:$P$1,0)) -> 355.32 | C24: =B24/$B$5*100 -> 32.965626 | D24: =IF(MONTH(A24)=1,YEAR(A24),"")
A25: =Prices!A13 -> 43800 | B25: =INDEX(Prices!$B$13:$P$13,MATCH($B$3,Prices!$B$1:$P$1,0)) -> 371.23 | C25: =B25/$B$5*100 -> 34.441713 | D25: =IF(MONTH(A25)=1,YEAR(A25),"")
A26: =Prices!A14 -> 43831 | B26: =INDEX(Prices!$B$14:$P$14,MATCH($B$3,Prices!$B$1:$P$1,0)) -> 340.87 | C26: =B26/$B$5*100 -> 31.624994 | D26: =IF(MONTH(A26)=1,YEAR(A26),"") -> 2020
A27: =Prices!A15 -> 43862 | B27: =INDEX(Prices!$B$15:$P$15,MATCH($B$3,Prices!$B$1:$P$1,0)) -> 358.49 | C27: =B27/$B$5*100 -> 33.25973 | D27: =IF(MONTH(A27)=1,YEAR(A27),"")
A28: =Prices!A16 -> 43891 | B28: =INDEX(Prices!$B$16:$P$16,MATCH($B$3,Prices!$B$1:$P$1,0)) -> 384.77 | C28: =B28/$B$5*100 -> 35.697917 | D28: =IF(MONTH(A28)=1,YEAR(A28),"")
A29: =Prices!A17 -> 43922 | B29: =INDEX(Prices!$B$17:$P$17,MATCH($B$3,Prices!$B$1:$P$1,0)) -> 405.23 | C29: =B29/$B$5*100 -> 37.59614 | D29: =IF(MONTH(A29)=1,YEAR(A29),"")
A30: =Prices!A18 -> 43952 | B30: =INDEX(Prices!$B$18:$P$18,MATCH($B$3,Prices!$B$1:$P$1,0)) -> 438.52 | C30: =B30/$B$5*100 -> 40.684696 | D30: =IF(MONTH(A30)=1,YEAR(A30),"")
A31: =Prices!A19 -> 43983 | B31: =INDEX(Prices!$B$19:$P$19,MATCH($B$3,Prices!$B$1:$P$1,0)) -> 465.04 | C31: =B31/$B$5*100 -> 43.14515 | D31: =IF(MONTH(A31)=1,YEAR(A31),"")
A32: =Prices!A20 -> 44013 | B32: =INDEX(Prices!$B$20:$P$20,MATCH($B$3,Prices!$B$1:$P$1,0)) -> 575.58 | C32: =B32/$B$5*100 -> 53.400751 | D32: =IF(MONTH(A32)=1,YEAR(A32),"")
A33: =Prices!A21 -> 44044 | B33: =INDEX(Prices!$B$21:$P$21,MATCH($B$3,Prices!$B$1:$P$1,0)) -> 709.92 | C33: =B33/$B$5*100 -> 65.864452 | D33: =IF(MONTH(A33)=1,YEAR(A33),"")
A34: =Prices!A22 -> 44075 | B34: =INDEX(Prices!$B$22:$P$22,MATCH($B$3,Prices!$B$1:$P$1,0)) -> 824.3 | C34: =B34/$B$5*100 -> 76.476319 | D34: =IF(MONTH(A34)=1,YEAR(A34),"")
A35: =Prices!A23 -> 44105 | B35: =INDEX(Prices!$B$23:$P$23,MATCH($B$3,Prices!$B$1:$P$1,0)) -> 763.39 | C35: =B35/$B$5*100 -> 70.825254 | D35: =IF(MONTH(A35)=1,YEAR(A35),"")
A36: =Prices!A24 -> 44136 | B36: =INDEX(Prices!$B$24:$P$24,MATCH($B$3,Prices!$B$1:$P$1,0)) -> 660.38 | C36: =B36/$B$5*100 -> 61.268266 | D36: =IF(MONTH(A36)=1,YEAR(A36),"")
A37: =Prices!A25 -> 44166 | B37: =INDEX(Prices!$B$25:$P$25,MATCH($B$3,Prices!$B$1:$P$1,0)) -> 741.36 | C37: =B37/$B$5*100 -> 68.78137 | D37: =IF(MONTH(A37)=1,YEAR(A37),"")
A38: =Prices!A26 -> 44197 | B38: =INDEX(Prices!$B$26:$P$26,MATCH($B$3,Prices!$B$1:$P$1,0)) -> 887.71 | C38: =B38/$B$5*100 -> 82.359326 | D38: =IF(MONTH(A38)=1,YEAR(A38),"") -> 2021
A39: =Prices!A27 -> 44228 | B39: =INDEX(Prices!$B$27:$P$27,MATCH($B$3,Prices!$B$1:$P$1,0)) -> 939.7 | C39: =B39/$B$5*100 -> 87.182818 | D39: =IF(MONTH(A39)=1,YEAR(A39),"")
A40: =Prices!A28 -> 44256 | B40: =INDEX(Prices!$B$28:$P$28,MATCH($B$3,Prices!$B$1:$P$1,0)) -> 1142.76 | C40: =B40/$B$5*100 -> 106.02217 | D40: =IF(MONTH(A40)=1,YEAR(A40),"")
A41: =Prices!A29 -> 44287 | B41: =INDEX(Prices!$B$29:$P$29,MATCH($B$3,Prices!$B$1:$P$1,0)) -> 1112.14 | C41: =B41/$B$5*100 -> 103.18133 | D41: =IF(MONTH(A41)=1,YEAR(A41),"")
A42: =Prices!A30 -> 44317 | B42: =INDEX(Prices!$B$30:$P$30,MATCH($B$3,Prices!$B$1:$P$1,0)) -> 1178.45 | C42: =B42/$B$5*100 -> 109.3334 | D42: =IF(MONTH(A42)=1,YEAR(A42),"")
A43: =Prices!A31 -> 44348 | B43: =INDEX(Prices!$B$31:$P$31,MATCH($B$3,Prices!$B$1:$P$1,0)) -> 1345.71 | C43: =B43/$B$5*100 -> 124.85132 | D43: =IF(MONTH(A43)=1,YEAR(A43),"")
A44: =Prices!A32 -> 44378 | B44: =INDEX(Prices!$B$32:$P$32,MATCH($B$3,Prices!$B$1:$P$1,0)) -> 1416.95 | C44: =B44/$B$5*100 -> 131.46078 | D44: =IF(MONTH(A44)=1,YEAR(A44),"")
...

Sheet Peak to now
A1: How far has each food fallen from its peak?
A2: National average prices in naira. Peak = highest month from Jan 2023 to Jul 2026. Every number below is a formula on the Prices sheet.
A4: Food | B4: Jan 2023 | C4: Peak | D4: Peak month | E4: Jul 2026 | F4: Rise to peak | G4: Down from peak | H4: Jan 2023 to now
A5: Beans (2.5 kg) | B5: =INDEX(Prices!$B$50:$P$92,1,MATCH($A5,Prices!$B$1:$P$1,0)) -> 1077.85 | C5: =MAX(INDEX(Prices!$B$50:$P$92,0,MATCH($A5,Prices!$B$1:$P$1,0))) -> 4596.67 | D5: =INDEX(Prices!$A$50:$A$92,MATCH(C5,INDEX(Prices!$B$50:$P$92,0,MATCH($A5,Prices!$B$1:$P$1,0)),0)) -> 45536 | E5: =INDEX(Prices!$B$50:$P$92,ROWS(Prices!$A$50:$A$92),MATCH($A5,Prices!$B$1:$P$1,0)) -> 2276.95 | F5: =C5/B5-1 -> 3.2646658 | G5: =E5/C5-1 -> -0.50465228 | H5: =E5/B5-1 -> 1.1124925
A6: Maize (1 kg) | B6: =INDEX(Prices!$B$50:$P$92,1,MATCH($A6,Prices!$B$1:$P$1,0)) -> 424.8 | C6: =MAX(INDEX(Prices!$B$50:$P$92,0,MATCH($A6,Prices!$B$1:$P$1,0))) -> 1524.34 | D6: =INDEX(Prices!$A$50:$A$92,MATCH(C6,INDEX(Prices!$B$50:$P$92,0,MATCH($A6,Prices!$B$1:$P$1,0)),0)) -> 45839 | E6: =INDEX(Prices!$B$50:$P$92,ROWS(Prices!$A$50:$A$92),MATCH($A6,Prices!$B$1:$P$1,0)) -> 829.65 | F6: =C6/B6-1 -> 2.588371 | G6: =E6/C6-1 -> -0.45573166 | H6: =E6/B6-1 -> 0.95303672
A7: Sorghum (1 kg) | B7: =INDEX(Prices!$B$50:$P$92,1,MATCH($A7,Prices!$B$1:$P$1,0)) -> 288.25 | C7: =MAX(INDEX(Prices!$B$50:$P$92,0,MATCH($A7,Prices!$B$1:$P$1,0))) -> 954.01 | D7: =INDEX(Prices!$A$50:$A$92,MATCH(C7,INDEX(Prices!$B$50:$P$92,0,MATCH($A7,Prices!$B$1:$P$1,0)),0)) -> 45505 | E7: =INDEX(Prices!$B$50:$P$92,ROWS(Prices!$A$50:$A$92),MATCH($A7,Prices!$B$1:$P$1,0)) -> 523.84 | F7: =C7/B7-1 -> 2.3096618 | G7: =E7/C7-1 -> -0.45090722 | H7: =E7/B7-1 -> 0.81731136
A8: Millet (2.6 kg) | B8: =INDEX(Prices!$B$50:$P$92,1,MATCH($A8,Prices!$B$1:$P$1,0)) -> 924 | C8: =MAX(INDEX(Prices!$B$50:$P$92,0,MATCH($A8,Prices!$B$1:$P$1,0))) -> 2680.69 | D8: =INDEX(Prices!$A$50:$A$92,MATCH(C8,INDEX(Prices!$B$50:$P$92,0,MATCH($A8,Prices!$B$1:$P$1,0)),0)) -> 45505 | E8: =INDEX(Prices!$B$50:$P$92,ROWS(Prices!$A$50:$A$92),MATCH($A8,Prices!$B$1:$P$1,0)) -> 1568.17 | F8: =C8/B8-1 -> 1.9011797 | G8: =E8/C8-1 -> -0.41501255 | H8: =E8/B8-1 -> 0.69715368
A9: Garri (1 kg) | B9: =INDEX(Prices!$B$50:$P$92,1,MATCH($A9,Prices!$B$1:$P$1,0)) -> 342.47 | C9: =MAX(INDEX(Prices!$B$50:$P$92,0,MATCH($A9,Prices!$B$1:$P$1,0))) -> 1299.83 | D9: =INDEX(Prices!$A$50:$A$92,MATCH(C9,INDEX(Prices!$B$50:$P$92,0,MATCH($A9,Prices!$B$1:$P$1,0)),0)) -> 45717 | E9: =INDEX(Prices!$B$50:$P$92,ROWS(Prices!$A$50:$A$92),MATCH($A9,Prices!$B$1:$P$1,0)) -> 826.79 | F9: =C9/B9-1 -> 2.7954565 | G9: =E9/C9-1 -> -0.36392451 | H9: =E9/B9-1 -> 1.4141969
A10: Maize flour (2.1 kg) | B10: =INDEX(Prices!$B$50:$P$92,1,MATCH($A10,Prices!$B$1:$P$1,0)) -> 792.75 | C10: =MAX(INDEX(Prices!$B$50:$P$92,0,MATCH($A10,Prices!$B$1:$P$1,0))) -> 2333.82 | D10: =INDEX(Prices!$A$50:$A$92,MATCH(C10,INDEX(Prices!$B$50:$P$92,0,MATCH($A10,Prices!$B$1:$P$1,0)),0)) -> 45474 | E10: =INDEX(Prices!$B$50:$P$92,ROWS(Prices!$A$50:$A$92),MATCH($A10,Prices!$B$1:$P$1,0)) -> 1554.01 | F10: =C10/B10-1 -> 1.9439546 | G10: =E10/C10-1 -> -0.33413459 | H10: =E10/B10-1 -> 0.96027751
A11: Fish (1 kg) | B11: =INDEX(Prices!$B$50:$P$92,1,MATCH($A11,Prices!$B$1:$P$1,0)) -> 368.95 | C11: =MAX(INDEX(Prices!$B$50:$P$92,0,MATCH($A11,Prices!$B$1:$P$1,0))) -> 1679.31 | D11: =INDEX(Prices!$A$50:$A$92,MATCH(C11,INDEX(Prices!$B$50:$P$92,0,MATCH($A11,Prices!$B$1:$P$1,0)),0)) -> 45992 | E11: =INDEX(Prices!$B$50:$P$92,ROWS(Prices!$A$50:$A$92),MATCH($A11,Prices!$B$1:$P$1,0)) -> 1129.57 | F11: =C11/B11-1 -> 3.5515924 | G11: =E11/C11-1 -> -0.32736064 | H11: =E11/B11-1 -> 2.0615802
A12: Rice (1 kg) | B12: =INDEX(Prices!$B$50:$P$92,1,MATCH($A12,Prices!$B$1:$P$1,0)) -> 832.12 | C12: =MAX(INDEX(Prices!$B$50:$P$92,0,MATCH($A12,Prices!$B$1:$P$1,0))) -> 2878.52 | D12: =INDEX(Prices!$A$50:$A$92,MATCH(C12,INDEX(Prices!$B$50:$P$92,0,MATCH($A12,Prices!$B$1:$P$1,0)),0)) -> 45717 | E12: =INDEX(Prices!$B$50:$P$92,ROWS(Prices!$A$50:$A$92),MATCH($A12,Prices!$B$1:$P$1,0)) -> 2200.03 | F12: =C12/B12-1 -> 2.4592607 | G12: =E12/C12-1 -> -0.23570793 | H12: =E12/B12-1 -> 1.6438855
A13: Groundnuts (2.2 kg) | B13: =INDEX(Prices!$B$50:$P$92,1,MATCH($A13,Prices!$B$1:$P$1,0)) -> 1168.88 | C13: =MAX(INDEX(Prices!$B$50:$P$92,0,MATCH($A13,Prices!$B$1:$P$1,0))) -> 3872.47 | D13: =INDEX(Prices!$A$50:$A$92,MATCH(C13,INDEX(Prices!$B$50:$P$92,0,MATCH($A13,Prices!$B$1:$P$1,0)),0)) -> 45658 | E13: =INDEX(Prices!$B$50:$P$92,ROWS(Prices!$A$50:$A$92),MATCH($A13,Prices!$B$1:$P$1,0)) -> 3127.08 | F13: =C13/B13-1 -> 2.3129748 | G13: =E13/C13-1 -> -0.19248438 | H13: =E13/B13-1 -> 1.6752789
A14: Onions (0.5 kg) | B14: =INDEX(Prices!$B$50:$P$92,1,MATCH($A14,Prices!$B$1:$P$1,0)) -> 155.11 | C14: =MAX(INDEX(Prices!$B$50:$P$92,0,MATCH($A14,Prices!$B$1:$P$1,0))) -> 513.49 | D14: =INDEX(Prices!$A$50:$A$92,MATCH(C14,INDEX(Prices!$B$50:$P$92,0,MATCH($A14,Prices!$B$1:$P$1,0)),0)) -> 45748 | E14: =INDEX(Prices!$B$50:$P$92,ROWS(Prices!$A$50:$A$92),MATCH($A14,Prices!$B$1:$P$1,0)) -> 443.71 | F14: =C14/B14-1 -> 2.3104893 | G14: =E14/C14-1 -> -0.13589359 | H14: =E14/B14-1 -> 1.860615
A15: Yam (2.5 kg) | B15: =INDEX(Prices!$B$50:$P$92,1,MATCH($A15,Prices!$B$1:$P$1,0)) -> 852 | C15: =MAX(INDEX(Prices!$B$50:$P$92,0,MATCH($A15,Prices!$B$1:$P$1,0))) -> 3157.43 | D15: =INDEX(Prices!$A$50:$A$92,MATCH(C15,INDEX(Prices!$B$50:$P$92,0,MATCH($A15,Prices!$B$1:$P$1,0)),0)) -> 45717 | E15: =INDEX(Prices!$B$50:$P$92,ROWS(Prices!$A$50:$A$92),MATCH($A15,Prices!$B$1:$P$1,0)) -> 2848.58 | F15: =C15/B15-1 -> 2.7059038 | G15: =E15/C15-1 -> -0.097816895 | H15: =E15/B15-1 -> 2.3434038
A16: Milk (400 g) | B16: =INDEX(Prices!$B$50:$P$92,1,MATCH($A16,Prices!$B$1:$P$1,0)) -> 1997.92 | C16: =MAX(INDEX(Prices!$B$50:$P$92,0,MATCH($A16,Prices!$B$1:$P$1,0))) -> 4138.99 | D16: =INDEX(Prices!$A$50:$A$92,MATCH(C16,INDEX(Prices!$B$50:$P$92,0,MATCH($A16,Prices!$B$1:$P$1,0)),0)) -> 45809 | E16: =INDEX(Prices!$B$50:$P$92,ROWS(Prices!$A$50:$A$92),MATCH($A16,Prices!$B$1:$P$1,0)) -> 3831.91 | F16: =C16/B16-1 -> 1.0716495 | G16: =E16/C16-1 -> -0.074192013 | H16: =E16/B16-1 -> 0.91794967
... A19: Goat meat (1 kg) | B19: =INDEX(Prices!$B$50:$P$92,1,MATCH($A19,Prices!$B$1:$P$1,0)) -> 1884.77 | C19: =MAX(INDEX(Prices!$B$50:$P$92,0,MATCH($A19,Prices!$B$1:$P$1,0))) -> 5572.99 | D19: =INDEX(Prices!$A$50:$A$92,MATCH(C19,INDEX(Prices!$B$50:$P$92,0,MATCH($A19,Prices!$B$1:$P$1,0)),0)) -> 45839 | E19: =INDEX(Prices!$B$50:$P$92,ROWS(Prices!$A$50:$A$92),MATCH($A19,Prices!$B$1:$P$1,0)) -> 5443.59 | F19: =C19/B19-1 -> 1.9568542 | G19: =E19/C19-1 -> -0.023219134 | H19: =E19/B19-1 -> 1.8881986

Sheet By zone
A1: Where does a basic plate cost the most?
A2: 1 kg each of rice, beans and garri, in naira. Formulas pull from the Zones sheet.
B3: 44927 | C3: 45717 | D3: 46204
A4: Zone | B4: Jan 2023 | C4: Mar 2025 (peak) | D4: Jul 2026 | E4: Fall since peak | F4: vs North West now
A5: South South | B5: =SUMIFS(Zones!$F:$F,Zones!$A:$A,B$3,Zones!$B:$B,$A5) -> 1610.776 | C5: =SUMIFS(Zones!$F:$F,Zones!$A:$A,C$3,Zones!$B:$B,$A5) -> 5299.754 | D5: =SUMIFS(Zones!$F:$F,Zones!$A:$A,D$3,Zones!$B:$B,$A5) -> 4011.102 | E5: =D5/C5-1 -> -0.24315317 | F5: =D5/$D$9-1 -> 0.25039185
A6: South East | B6: =SUMIFS(Zones!$F:$F,Zones!$A:$A,B$3,Zones!$B:$B,$A6) -> 1699.992 | C6: =SUMIFS(Zones!$F:$F,Zones!$A:$A,C$3,Zones!$B:$B,$A6) -> 5411.372 | D6: =SUMIFS(Zones!$F:$F,Zones!$A:$A,D$3,Zones!$B:$B,$A6) -> 3971.342 | E6: =D6/C6-1 -> -0.26611181 | F6: =D6/$D$9-1 -> 0.23799735
A7: North Central | B7: =SUMIFS(Zones!$F:$F,Zones!$A:$A,B$3,Zones!$B:$B,$A7) -> 1427.236 | C7: =SUMIFS(Zones!$F:$F,Zones!$A:$A,C$3,Zones!$B:$B,$A7) -> 5218.65 | D7: =SUMIFS(Zones!$F:$F,Zones!$A:$A,D$3,Zones!$B:$B,$A7) -> 3742.222 | E7: =D7/C7-1 -> -0.28291378 | F7: =D7/$D$9-1 -> 0.16657315
A8: South West | B8: =SUMIFS(Zones!$F:$F,Zones!$A:$A,B$3,Zones!$B:$B,$A8) -> 1491.086 | C8: =SUMIFS(Zones!$F:$F,Zones!$A:$A,C$3,Zones!$B:$B,$A8) -> 4817.204 | D8: =SUMIFS(Zones!$F:$F,Zones!$A:$A,D$3,Zones!$B:$B,$A8) -> 3716.67 | E8: =D8/C8-1 -> -0.22845908 | F8: =D8/$D$9-1 -> 0.15860775
A9: North West | B9: =SUMIFS(Zones!$F:$F,Zones!$A:$A,B$3,Zones!$B:$B,$A9) -> 1440.476 | C9: =SUMIFS(Zones!$F:$F,Zones!$A:$A,C$3,Zones!$B:$B,$A9) -> 5449.124 | D9: =SUMIFS(Zones!$F:$F,Zones!$A:$A,D$3,Zones!$B:$B,$A9) -> 3207.876 | E9: =D9/C9-1 -> -0.41130428 | F9: =D9/$D$9-1 -> 0

Sheet Prices
A1: Month | B1: Beans (2.5 kg) | C1: Maize (1 kg) | D1: Sorghum (1 kg) | E1: Millet (2.6 kg) | F1: Garri (1 kg) | G1: Maize flour (2.1 kg) | H1: Fish (1 kg) | I1: Rice (1 kg) | J1: Groundnuts (2.2 kg) | K1: Onions (0.5 kg) | L1: Yam (2.5 kg) | M1: Milk (400 g) | N1: Eggs (30) | O1: Beef (1 kg) | P1: Goat meat (1 kg)
A2: 43466 | B2: 536.73 | C2: 210.95 | D2: 115.01 | E2: 418.39 | F2: 168.6 | G2: 434.27 | H2: 185.42 | I2: 436.9 | J2: 635.58 | K2: 138.86 | L2: 537.73 | M2: 983.19 | N2: 1034.72 | O2: 1203.05 | P2: 1185.18
A3: 43497 | B3: 539.41 | C3: 211.71 | D3: 110.11 | E3: 419.58 | F3: 168.18 | G3: 410.49 | H3: 211.63 | I3: 401.18 | J3: 575.46 | K3: 127.4 | L3: 533.23 | M3: 981.62 | N3: 1025.79 | O3: 1199.96 | P3: 1172.2
A4: 43525 | B4: 555.47 | C4: 213.17 | D4: 118.24 | E4: 426.05 | F4: 165.75 | G4: 425.62 | H4: 212.49 | I4: 424.23 | J4: 640.62 | K4: 130.79 | L4: 547.5 | M4: 980.77 | N4: 1008.1 | O4: 1190.09 | P4: 1170.47
A5: 43556 | B5: 488.5 | C5: 212 | D5: 117.12 | E5: 415.82 | F5: 166.96 | G5: 411.75 | H5: 139.18 | I5: 420.18 | J5: 595.67 | K5: 121.15 | L5: 511.02 | M5: 977.13 | N5: 1019.67 | O5: 1178.61 | P5: 1182.66
A6: 43586 | B6: 457.3 | C6: 210.98 | D6: 119.06 | E6: 409.61 | F6: 166.47 | G6: 417.59 | H6: 134.25 | I6: 436.26 | J6: 612.77 | K6: 111.88 | L6: 483.45 | M6: 979.97 | N6: 1024.46 | O6: 1162.95 | P6: 1184.53
A7: 43617 | B7: 462.76 | C7: 201.73 | D7: 115.39 | E7: 400.61 | F7: 160.56 | G7: 420.18 | H7: 146.88 | I7: 430.88 | J7: 626.62 | K7: 111.16 | L7: 518.93 | M7: 981.04 | N7: 1018.63 | O7: 1170.59 | P7: 1175.48
A8: 43647 | B8: 426.73 | C8: 198.05 | D8: 113.41 | E8: 405.07 | F8: 166.41 | G8: 409.82 | H8: 154.12 | I8: 427.05 | J8: 675.1 | K8: 88.9 | L8: 548.71 | M8: 978.94 | N8: 1027.38 | O8: 1154.45 | P8: 1138.38
A9: 43678 | B9: 411.69 | C9: 199.06 | D9: 116.46 | E9: 400.03 | F9: 165.89 | G9: 401.35 | H9: 132.19 | I9: 432.75 | J9: 645 | K9: 93.22 | L9: 519.76 | M9: 977 | N9: 1003.4 | O9: 1142.86 | P9: 1143.72
A10: 43709 | B10: 460.77 | C10: 205.65 | D10: 119.8 | E10: 402 | F10: 160.36 | G10: 418.37 | H10: 156.95 | I10: 480.06 | J10: 656.16 | K10: 125.74 | L10: 496.34 | M10: 980.74 | N10: 1012.16 | O10: 1166.05 | P10: 1156.57
A11: 43739 | B11: 352.99 | C11: 201.87 | D11: 117.5 | E11: 398.42 | F11: 170.87 | G11: 417.28 | H11: 97.77 | I11: 544.71 | J11: 668.4 | K11: 95.92 | L11: 434.2 | M11: 980.51 | N11: 1023.69 | O11: 1172.98 | P11: 1181.99
A12: 43770 | B12: 355.32 | C12: 204.24 | D12: 117.96 | E12: 405.28 | F12: 175.35 | G12: 418.64 | H12: 99.24 | I12: 546.4 | J12: 651.44 | K12: 97.13 | L12: 427.99 | M12: 980.5 | N12: 1014.63 | O12: 1156.08 | P12: 1184.13
A13: 43800 | B13: 371.23 | C13: 200.01 | D13: 115.39 | E13: 400 | F13: 179.96 | G13: 411.74 | H13: 110.02 | I13: 492.83 | J13: 645.63 | K13: 84.79 | L13: 468.11 | M13: 983.44 | N13: 1015.97 | O13: 1135.37 | P13: 1160.62
... A92: 46204 | B92: 2276.95 | C92: 829.65 | D92: 523.84 | E92: 1568.17 | F92: 826.79 | G92: 1554.01 | H92: 1129.57 | I92: 2200.03 | J92: 3127.08 | K92: 443.71 | L92: 2848.58 | M92: 3831.91 | N92: 5986.92 | O92: 6360.79 | P92: 5443.59
A94: Naira, national average across markets. Source: World Bank, Monthly food price estimates by product and market, Nigeria (NGA_RTFP_mkt_2007_2026-08-03.csv). Monthly estimated (close) prices.

Sheet Zones
A1: Month | B1: Zone | C1: Rice (1 kg) | D1: Beans (2.5 kg) | E1: Garri (1 kg) | F1: Plate cost
A2: 43466 | B2: North Central | C2: 361.06 | D2: 555.96 | E2: 181.37 | F2: =C2+D2/2.5+E2 -> 764.814
A3: 43466 | B3: North West | C3: 315.66 | D3: 562.77 | E3: 178.08 | F3: =C3+D3/2.5+E3 -> 718.848
A4: 43466 | B4: South East | C4: 414.6 | D4: 516.57 | E4: 156.72 | F4: =C4+D4/2.5+E4 -> 777.948
A5: 43466 | B5: South South | C5: 430.73 | D5: 561.52 | E5: 161.53 | F5: =C5+D5/2.5+E5 -> 816.868
A6: 43466 | B6: South West | C6: 348.28 | D6: 560.36 | E6: 130.85 | F6: =C6+D6/2.5+E6 -> 703.274
A7: 43497 | B7: North Central | C7: 368.77 | D7: 547.28 | E7: 179.42 | F7: =C7+D7/2.5+E7 -> 767.102
A8: 43497 | B8: North West | C8: 323.59 | D8: 525.63 | E8: 169.87 | F8: =C8+D8/2.5+E8 -> 703.712
A9: 43497 | B9: South East | C9: 409.93 | D9: 518.39 | E9: 158.06 | F9: =C9+D9/2.5+E9 -> 775.346
A10: 43497 | B10: South South | C10: 423.78 | D10: 572.7 | E10: 168.4 | F10: =C10+D10/2.5+E10 -> 821.26
A11: 43497 | B11: South West | C11: 334.13 | D11: 592.7 | E11: 130.82 | F11: =C11+D11/2.5+E11 -> 702.03
A12: 43525 | B12: North Central | C12: 369.39 | D12: 523.01 | E12: 166.18 | F12: =C12+D12/2.5+E12 -> 744.774
A13: 43525 | B13: North West | C13: 321.94 | D13: 504.79 | E13: 168.02 | F13: =C13+D13/2.5+E13 -> 691.876
... A456: 46204 | B456: South West | C456: 2121.61 | D456: 2041.45 | E456: 778.48 | F456: =C456+D456/2.5+E456 -> 3716.67
A458: Plate cost = 1 kg rice + 1 kg beans + 1 kg garri, in naira. Beans are priced per 2.5 kg, so they're divided by 2.5. Same source as the Prices sheet.
